<?xml version="1.0"?>
<robot xmlns:xacro="http://www.ros.org/wiki/xacro" >

    <xacro:include filename="inertial_macros.xacro" />
    <!-- <xacro:include filename="lidar.xacro" />    -->
    <material name="white">
        <color rgba="1 1 1 1" />
    </material>

    <material name="orange">
        <color rgba="1 0.3 0.1 1"/>
    </material>

    <material name="blue">
        <color rgba="0.2 0.2 1 1"/>
    </material>

    <material name="black">
        <color rgba="0 0 0 1"/>
    </material>

    <material name="red">
        <color rgba="1 0 0 1"/>
    </material>

    <!-- BASE LINK -->

    <link name="base_link">

    </link>

    <joint name="chassis_joint" type="fixed">
        <parent link="base_link"/>
        <child link="chassis"/>
        <origin xyz="0 0 0"/>
        <dynamics damping="1" friction="1"/>
    </joint>

    <link name="chassis">
        <visual>
            <origin xyz="-0.25 0.25 0" rpy="0 0 0"/>
            <geometry>
                <mesh filename="file:///home/pondza/robofinal4_ws/src/articubot_one/description/car_body.dae"/>
            </geometry>
            <material name="white"/>
        </visual>
        <collision>
            <origin xyz="-0.25 0.25 0" rpy="0 0 0"/>
            <geometry>
                <mesh filename="file:///home/pondza/robofinal4_ws/src/articubot_one/description/car_body.dae"/>
            </geometry>
        </collision>
        <xacro:inertial_box mass="2" x="0.5" y="0.5" z="0.35">
            <origin xyz="0 0 0.175" rpy="0 0 0"/>
        </xacro:inertial_box>
    </link>

    <gazebo reference="chassis">
        <material>Gazebo/White</material>
        <mu1 value="0.1"/>
        <mu2 value="0.1"/>
    </gazebo>

    <!-- LEFT WHEEL -->

    <joint name="left_front_wheel_joint" type="continuous">
        <parent link="chassis"/>
        <child link="left_front_wheel"/>
        <origin xyz="0.15 0.27 0.03" rpy="-${pi/2} 0 0"/>
        <axis xyz="0 0 1"/>
        <dynamics damping="1" friction="1"/>
    </joint>

    <link name="left_front_wheel">
        <visual>
            <origin xyz="0 0 0" rpy="0 0 0"/>
            <geometry>
                <cylinder length="0.04" radius="0.1" />
            </geometry>
            <material name="blue"/>
        </visual>
        <collision>
            <geometry>
                <cylinder length="0.04" radius="0.1" />
            </geometry>
        </collision>
        <xacro:inertial_cylinder mass="0.1" length="0.04" radius="0.1">
            <origin xyz="0 0 0" rpy="0 0 0"/>
        </xacro:inertial_cylinder>
    </link>

    <gazebo reference="left_front_wheel">
        <material>Gazebo/Black</material>
        <mu1 value="0.1"/>
        <mu2 value="0.1"/>
    </gazebo>

    <joint name="left_back_wheel_joint" type="continuous">
        <parent link="chassis"/>
        <child link="left_back_wheel"/>
        <origin xyz="-0.15 0.27 0.03" rpy="-${pi/2} 0 0"/>
        <axis xyz="0 0 1"/>
        <dynamics damping="1" friction="1"/>
    </joint>

    <link name="left_back_wheel">
        <visual>
            <origin xyz="0 0 0" rpy="0 0 0"/>
            <geometry>
                <cylinder length="0.04" radius="0.1" />
            </geometry>
            <material name="blue"/>
        </visual>
        <collision>
            <geometry>
                <cylinder length="0.04" radius="0.1" />
            </geometry>
        </collision>
        <xacro:inertial_cylinder mass="0.1" length="0.04" radius="0.1">
            <origin xyz="0 0 0" rpy="0 0 0"/>
        </xacro:inertial_cylinder>
    </link>

    <gazebo reference="left_back_wheel">
        <material>Gazebo/Black</material>
        <mu1 value="0.1"/>
        <mu2 value="0.1"/>
    </gazebo> 

     <!-- RIGHT WHEEL -->

    <joint name="right_front_wheel_joint" type="continuous">
        <parent link="chassis"/>
        <child link="right_front_wheel"/>
        <origin xyz="0.15 -0.27 0.03" rpy="${pi/2} 0 0"/>
        <axis xyz="0 0 -1"/>
        <dynamics damping="1" friction="1"/>
    </joint>

    <link name="right_front_wheel">
        <visual>
            <origin xyz="0 0 0" rpy="0 0 0"/>
            <geometry>
                <cylinder length="0.04" radius="0.1" />
            </geometry>
            <material name="blue"/>
        </visual>
        <collision>
            <geometry>
                <cylinder length="0.04" radius="0.1" />
            </geometry>
        </collision>
        <xacro:inertial_cylinder mass="0.1" length="0.04" radius="0.1">
            <origin xyz="0 0 0" rpy="0 0 0"/>
        </xacro:inertial_cylinder>
    </link>

    <gazebo reference="right_front_wheel">
        <material>Gazebo/Black</material>
        <mu1 value="0.1"/>
        <mu2 value="0.1"/>
    </gazebo>

    <joint name="right_back_wheel_joint" type="continuous">
        <parent link="chassis"/>
        <child link="right_back_wheel"/>
        <origin xyz="-0.15 -0.27 0.03" rpy="${pi/2} 0 0"/>
        <axis xyz="0 0 -1"/>
        <dynamics damping="1" friction="1"/>
    </joint>

    <link name="right_back_wheel">
        <visual>
            <origin xyz="0 0 0" rpy="0 0 0"/>
            <geometry>
                <cylinder length="0.04" radius="0.1" />
            </geometry>
            <material name="blue"/>
        </visual>
        <collision>
            <origin xyz="0 0 0" rpy="0 0 0"/>
            <geometry>
                <cylinder length="0.04" radius="0.1" />
            </geometry>
        </collision>
        <xacro:inertial_cylinder mass="0.1" length="0.04" radius="0.1">
            <origin xyz="0 0 0" rpy="0 0 0"/>
        </xacro:inertial_cylinder>
    </link>

    <gazebo reference="right_back_wheel">
        <material>Gazebo/Black</material>
        <mu1 value="0.1"/>
        <mu2 value="0.1"/>
    </gazebo> 

    <!-- Robot Arm  -->

     <joint name="robot_base_joint" type="fixed">
        <parent link="base_link"/>
        <child link="robot_base"/>
        <origin xyz="-0.05 0 0.3" rpy="0 0 0"/>
        <axis xyz="0 0 0"/>
        <dynamics damping="1" friction="1"/>
    </joint>

    <link name="robot_base">
        <visual>
            <origin xyz="-0.1 0.13 0" rpy="0 0 0"/>
            <geometry>
                <mesh filename="file:///home/pondza/robofinal4_ws/src/articubot_one/description/robot_base2.dae"/>
            </geometry>
        </visual>
        <collision>
            <origin xyz="-0.1 0.13 0" rpy="0 0 0"/>
            <geometry>
                <mesh filename="file:///home/pondza/robofinal4_ws/src/articubot_one/description/robot_base2.dae"/>
            </geometry>
        </collision>
        <xacro:inertial_cylinder mass="0.5" length="0.5" radius="0.1">
            <origin xyz="0 0 0" rpy="0 0 0"/>
        </xacro:inertial_cylinder>
    </link>

   <joint name="lower_arm_joint" type="revolute">
        <parent link="chassis"/>
        <child link="lower_arm"/>
        <origin xyz="0 0 0.5" rpy="0 0 0"/>
        <axis xyz="0 1 0"/>
        <limit lower="-0.37" upper="0.37" effort="0.5" velocity="0.0" />
        <dynamics damping="1" friction="1"/>
    </joint>

    <link name="lower_arm">
        <visual>
            <origin xyz="-0.4 -0.28 -0.1" rpy="0 0 0"/>
            <geometry>
                <mesh filename="file:///home/pondza/robofinal4_ws/src/articubot_one/description/arm_5.dae"/>
            </geometry>
            <material name="orange"/>
        </visual>
        <collision>
            <origin xyz="-0.4 -0.28 -0.1" rpy="0 0 0"/>
            <geometry>
                <mesh filename="file:///home/pondza/robofinal4_ws/src/articubot_one/description/arm_5.dae"/>
            </geometry>
        </collision>
        <xacro:inertial_cylinder mass="0.01" length="1" radius="0.075">
            <origin xyz="0.2 -0.175 0" rpy="0 ${pi/2} 0"/>
        </xacro:inertial_cylinder>
    </link>

    <gazebo reference="lower_arm">
        <material>Gazebo/White</material>
        <mu1 value="0.1"/>
        <mu2 value="0.1"/>
    </gazebo> 

    <!-- Gripper  -->

    <joint name="gripper_base_joint" type="fixed">
        <parent link="lower_arm"/>
        <child link="gripper_base"/>
        <origin xyz="0 0 0" rpy="0 0 0"/>
        <axis xyz="1 0 0"/>
        <dynamics damping="1" friction="1"/>
    </joint>

    <link name="gripper_base">
        <visual>
            <origin xyz="0.75 -0.075 0.1" rpy="${pi/2} ${pi/2} 0"/>
            <geometry>
                <mesh filename="file:///home/pondza/robofinal4_ws/src/articubot_one/description/gripper_base.dae"/>
            </geometry>
            <material name="orange"/>
        </visual>
        <collision>
            <origin xyz="0.75 -0.075 0.1" rpy="${pi/2} ${pi/2} 0"/>
            <geometry>
                <mesh filename="file:///home/pondza/robofinal4_ws/src/articubot_one/description/gripper_base.dae"/>
            </geometry>
        </collision>
        <xacro:inertial_box mass="0.1" x="0.1" y="0.1" z="0.1">
            <origin xyz="0 0 0" rpy="0 0 0"/>
        </xacro:inertial_box>
    </link>

    <joint name="gripper_hand_left_joint" type="prismatic">
        <parent link="gripper_base"/>
        <child link="gripper_left_arm"/>
        <origin xyz="0 0 0" rpy="0 0 0"/>
        <axis xyz="0 1 0"/>
        <limit lower="-0.1" upper="0.1" effort="0.5" velocity="0.1" />
        <dynamics damping="1" friction="1"/>
    </joint>

    <link name="gripper_left_arm">
        <visual>
            <origin xyz="0.875 -0.075 0" rpy="${pi/2} ${pi/2} 0"/>
            <geometry>
                <box size="0.2 0.1 0.05"/>
            </geometry>
        </visual>
        <collision>
            <origin xyz="0.875 -0.075 0" rpy="${pi/2} ${pi/2} 0"/>
            <geometry>
                <box size="0.2 0.1 0.05"/>
            </geometry>
        </collision>
        <xacro:inertial_box mass="0.1" x="0.1" y="0.1" z="0.1">
            <origin xyz="0 0 0" rpy="0 0 0"/>
        </xacro:inertial_box>
    </link>

    <gazebo reference="gripper_left_arm">
        <material>Gazebo/White</material>
        <mu1 value="0.1"/>
        <mu2 value="0.1"/>
    </gazebo>

    <joint name="gripper_hand_right_joint" type="prismatic">
        <parent link="gripper_base"/>
        <child link="gripper_right_arm"/>
        <origin xyz="0 0 0" rpy="0 0 0"/>
        <axis xyz="0 1 0"/>
        <limit lower="-0.1" upper="0.1" effort="0.5" velocity="0.1" />
        <dynamics damping="1" friction="1"/>
    </joint>

    <link name="gripper_right_arm">
        <visual>
            <origin xyz="0.875 -0.325 0" rpy="${pi/2} ${pi/2} 0"/>
            <geometry>
                <box size="0.2 0.1 0.05"/>
            </geometry>
        </visual>
        <collision>
            <origin xyz="0.875 -0.325 0" rpy="${pi/2} ${pi/2} 0"/>
            <geometry>
                <box size="0.2 0.1 0.05"/>
            </geometry>
        </collision>
        <xacro:inertial_box mass="0.1" x="0.1" y="0.1" z="0.1">
            <origin xyz="0 0 0" rpy="0 0 0"/>
        </xacro:inertial_box>
    </link>

    <gazebo reference="gripper_right_arm">
        <material>Gazebo/White</material>
        <mu1 value="0.1"/>
        <mu2 value="0.1"/>
    </gazebo> 

    <!-- LiDAR -->

    <!-- <joint name="laser_joint" type="fixed">
        <parent link="chassis"/>
        <child link="laser_frame"/>
        <origin xyz="0.2 0 0.25" rpy="0 0 0"/>
    </joint>
 
    <link name="laser_frame">
        <visual>
            <geometry>
                <cylinder radius="0.05" length="0.005"/>
            </geometry>
            <material name="Black"/>
        </visual>
        <collision>
            <geometry>
                <cylinder radius="0.05" length="0.005"/>
            </geometry>
        </collision>
        <xacro:inertial_cylinder mass="0.1" length="0.005" radius="0.05">
            <origin xyz="0 0 0" rpy="0 0 0"/>
        </xacro:inertial_cylinder>
    </link>
 
    <gazebo reference="laser_frame">
        <material>Gazebo/Black</material>
 
        <sensor name="laser" type="ray">
            <pose> 0 0 0 0 0 0 </pose>
            <visualize>true</visualize>
            <update_rate>10</update_rate>
            <ray>
                <scan>
                    <horizontal>
                        <samples>360</samples>
                        <min_angle>-3.14</min_angle>
                        <max_angle>3.14</max_angle>
                    </horizontal>
                </scan>
                <range>
                    <min>0.5</min>
                    <max>12</max>
                </range>
            </ray>
            
            <plugin name="laser_controller" filename="libgazebo_ros_ray_sensor.so">
                <ros>
                    <argument>~/out:=scan</argument>
                </ros>
                <output_type>sensor_msgs/LaserScan</output_type>
                <frame_name>laser_frame</frame_name>
            </plugin>
        </sensor>
    </gazebo>  
    -->
</robot>